Workbook

Sheet 법인카드
A1: 1. 법인카드 정산 마감
A2: - 마감시한: 익월 10일(사전 경고 후 법인카드 한도 조정)
A3: - 전표입력: 개인별 이용내역조회 시트는 마감일 3일이내 업데이트 → 권나영과장요청
A4: 2. 현금영수증
A5: - 계좌이체나 현금사용 시 증빙은 개인으로 하지마시고, '사업자지출증빙'으로 발급(주식회사 휴바이오켐 648-81-03114)
A6: 3. 간이계산서
A7: - 간이영수증을 받아야 하는 경우는 '3만원 한도'
A8: 4. 세금계산서
A9: - 세금계산서는 익월 10일에 마감되니, 가급적 거래완료 후 바로 발급요청
A10: 5. 영수증 실물 제출
A11: - 개인카드영수증: 미제출 시 비용정산 불가
A12: - 법인카드영수증: 마트 및 편의점 구매영수증(금액과 상관없이 의무 제출 - 구매내역 포함), 일반 구매영수증 10만원 이상 영수증
... A14: - 유가증권: 상품권, 기프티콘(단, 사전 기안에 의한 승인 시 가능, 반드시 상품권수령동의서 제출 필요)
A19: 날짜 | C19: 법인 or 개인 | D19: 카드 or 현금 | E19: 내역 | F19: 지 출 금 액 | J19: 거래처 | L19: 적요 | M19: 상호 | N19: 비고 | O19: 담당자
F20: 법인카드 | G20: 법인현금 | H20: 개인카드 | I20: 개인현금
F21: =F22+H22 -> 1103898 | J21: 상호 | K21: 담당자
A22: 월 | B22: 일 | F22: =F23+G23 -> 1103898 | H22: =SUM(H23:I23) -> 0
F23: =SUM(F142:F163) -> 1103898 | G23: =SUM(G24:G53) -> 0 | H23: =SUM(H24:H53) -> 0 | I23: =SUM(I24:I53) -> 0
A24: =MID(#REF!, 6, 2) -> #REF! | B24: =MID(#REF!, 9, 2) -> #REF! | C24: 법인 | D24: 카드 | E24: 식대 | F24: =#REF! -> #REF! | L24: 석식 (권영태, 남상민) | M24: 한국맥도날드(유)
A25: =MID(#REF!, 6, 2) -> #REF! | B25: =MID(#REF!, 9, 2) -> #REF! | C25: 법인 | D25: 카드 | E25: 식대 | F25: =#REF! -> #REF! | L25: 중식 (권영태, 남상민) | M25: 진국설렁탕
A26: =MID(#REF!, 6, 2) -> #REF! | B26: =MID(#REF!, 9, 2) -> #REF! | C26: 법인 | D26: 카드 | E26: 교통비 | F26: =#REF! -> #REF! | L26: 출근 택시비 | M26: 로카모빌리티택시_0
A27: =MID(#REF!, 6, 2) -> #REF! | B27: =MID(#REF!, 9, 2) -> #REF! | C27: 법인 | D27: 카드 | E27: 식대 | F27: =#REF! -> #REF! | L27: 출장 점심 | M27: 아모제푸드(주)인천공항점
A28: =MID(#REF!, 6, 2) -> #REF! | B28: =MID(#REF!, 9, 2) -> #REF! | C28: 법인 | D28: 카드 | E28: 교통비 | F28: =#REF! -> #REF! | L28: 출장 복귀 택시비 | M28: 티머니개인택시(K)1
A29: =MID(#REF!, 6, 2) -> #REF! | B29: =MID(#REF!, 9, 2) -> #REF! | C29: 법인 | D29: 카드 | E29: 식대 | F29: =#REF! -> #REF! | L29: 중식 (남상민, 권나영) | M29: 다락회전초밥
A30: =MID(#REF!, 6, 2) -> #REF! | B30: =MID(#REF!, 9, 2) -> #REF! | C30: 법인 | D30: 카드 | E30: 소모품 | F30: =#REF! -> #REF! | L30: 장갑 구입 | M30: (주)컴투프리테크 당산지점
A31: =MID(#REF!, 6, 2) -> #REF! | B31: =MID(#REF!, 9, 2) -> #REF! | C31: 법인 | D31: 카드 | E31: 식대 | F31: =#REF! -> #REF! | L31: 중식 (남상민, 권나영) | M31: 본리왕뼈해장국
A32: =MID(#REF!, 6, 2) -> #REF! | B32: =MID(#REF!, 9, 2) -> #REF! | C32: 법인 | D32: 카드 | E32: 식대 | F32: =#REF! -> #REF! | L32: 중식 (남상민, 권나영) | M32: 신사부대찌개&품격삼겹살
A33: =MID(#REF!, 6, 2) -> #REF! | B33: =MID(#REF!, 9, 2) -> #REF! | C33: 법인 | D33: 카드 | E33: 소프트웨어 구매 | F33: =#REF! -> #REF! | L33: MS Office 사용료 | M33: MICROSOFT-G098642730
A34: =MID(#REF!, 6, 2) -> #REF! | B34: =MID(#REF!, 9, 2) -> #REF! | C34: 법인 | D34: 카드 | E34: 식대 | F34: =#REF! -> #REF! | L34: 출장 중식 (남상민) | M34: 국수나무 당산SK점 | O34: 남상민
A35: =MID(#REF!, 6, 2) -> #REF! | B35: =MID(#REF!, 9, 2) -> #REF! | C35: 법인 | D35: 카드 | E35: 식대 | F35: =#REF! -> #REF! | L35: 출장 중식 (남상민) | M35: 국수나무 당산SK점 | O35: 남상민
A36: =MID(#REF!, 6, 2) -> #REF! | B36: =MID(#REF!, 9, 2) -> #REF! | C36: 법인 | D36: 카드 | E36: 식대 | F36: =#REF! -> #REF! | L36: 석식 (권영태, 남상민, 김민재) | M36: 상하이몽 | O36: 남상민
A37: =MID(#REF!, 6, 2) -> #REF! | B37: =MID(#REF!, 9, 2) -> #REF! | C37: 법인 | D37: 카드 | E37: 식대 | F37: =#REF! -> #REF! | L37: 중식 (양도영, 남상민, 김민재) | M37: 일번지비빔국수 서충주점 | O37: 남상민
A38: =MID(#REF!, 6, 2) -> #REF! | B38: =MID(#REF!, 9, 2) -> #REF! | C38: 법인 | D38: 카드 | E38: 식대 | F38: =#REF! -> #REF! | L38: 중식 (권영태, 남상민, 김민재) | M38: 태태식당 | O38: 남상민
A39: =MID(#REF!, 6, 2) -> #REF! | B39: =MID(#REF!, 9, 2) -> #REF! | C39: 법인 | D39: 카드 | E39: 간식 | F39: =#REF! -> #REF! | L39: 음료(남상민, 권나영) | M39: 바나프레소당산SK점 | O39: 남상민
A40: =MID(#REF!, 6, 2) -> #REF! | B40: =MID(#REF!, 9, 2) -> #REF! | C40: 법인 | D40: 카드 | E40: 식대 | F40: =#REF! -> #REF! | L40: 중식 (남상민) | M40: 산뽀갈땐김밥 | O40: 남상민
A41: =MID(#REF!, 6, 2) -> #REF! | B41: =MID(#REF!, 9, 2) -> #REF! | C41: 법인 | D41: 카드 | E41: 식대 | F41: =#REF! -> #REF! | L41: 중식(텔콘 정다운, 텔콘 양희준, 남상민) | M41: 중앙탑한우 | O41: 남상민
A42: =MID(#REF!, 6, 2) -> #REF! | B42: =MID(#REF!, 9, 2) -> #REF! | C42: 법인 | D42: 카드 | E42: 숙박비 | F42: =#REF! -> #REF! | L42: 텔콘 출장 숙박 (남상민) | M42: 리베파크 | O42: 남상민
A43: =MID(#REF!, 6, 2) -> #REF! | B43: =MID(#REF!, 9, 2) -> #REF! | C43: 법인 | D43: 카드 | E43: 식대 | F43: =#REF! -> #REF! | L43: 석식 (남상민, 김민재) | M43: 쿠팡이츠_쿠팡이츠_나이스 | O43: 남상민
A44: =MID(#REF!, 6, 2) -> #REF! | B44: =MID(#REF!, 9, 2) -> #REF! | C44: 법인 | D44: 카드 | E44: 식대 | F44: =#REF! -> #REF! | L44: 중식 (권영태, 남상민, 김민재) | M44: 김둘레순대국 | O44: 남상민
A45: =MID(#REF!, 6, 2) -> #REF! | B45: =MID(#REF!, 9, 2) -> #REF! | C45: 법인 | D45: 카드 | E45: 식대 | F45: =#REF! -> #REF! | L45: 석식 (남상민, 김민재) | M45: 쿠팡이츠_쿠팡이츠_KCP | O45: 남상민
...

Sheet Sheet1
